Workbook

Sheet 说明
B2: 挖矿游戏 · 矿物数据库
B3: 工业矿物 / 常见宝石矿物 / 化石 / 珍稀晶体矿物 —— 每个地形都有一个占 50% 概率的基底废料矿，稀有度越高概率越低
B6: 【核心概率模型（类黄金矿工）】
B7: · 每个地形固定一种「基底矿」（石头/沙子/碎石之类），单独占 50% 的产出概率——对应黄金矿工里满屏幕的石头，量大但相对不值钱。基底矿的售价随地形解锁顺序递增（平原3金 → 深层洞穴50金），门票越贵的地形，连最常见的废料也更值钱一点，避免高门槛地形的收益完全靠稀有矿物撑起来。
B8: · 剩下 50% 按稀有度分配，单个矿物的概率是固定值：传说 0.1%、史诗 0.5%、稀有 2%、少见 6%。同一地形里稀有度相同的矿物概率完全一样。普通矿物（不含基底矿）平分剩余的概率份额。
B9: · 这些固定值在「稀有度固定概率设置」表里，改那 4 个数字，全部地形自动重新计算，且每个地形合计仍是 100%。
B11: 【矿物分类说明】
B12: 四大分类：工业矿物 / 常见宝石矿物 / 珍稀晶体矿物 / 化石。
B13: · 工业矿物：矿石、燃料、建材等生产资料，包括各地形的基底废料矿。
B14: · 常见宝石矿物：普通人在珠宝店、纪念品店就能见到、认知度较高的宝石/观赏石（钻石、红蓝宝石、祖母绿、翡翠、和田玉、各类水晶等）。
B15: · 珍稀晶体矿物：矿物收藏圈才熟悉的稀有品种，普通人基本没听说过，多为特定产地、特定成因的稀有矿物（磷叶石、辰砂、蓝锥矿、南极石等），适合做地形里的顶级稀有掉落。
B16: · 化石：生物遗骸的矿化产物。
... B35: · 同一个矿物可以出现在多个地形里（比如石英砂同时是沙漠的基底矿、山地的常见矿），价格在矿物图鉴里只有一份、全局统一，不会因为出现在哪个地形而不同，只有出现概率会按地形分别计算。

Sheet 矿物图鉴
A1: 矿物名称 | B1: 分类 | C1: 稀有度 | D1: 化学式 | E1: 基础售价（金币） | F1: 备注 / 特殊机制
A2: 铁矿石 | B2: 工业矿物 | C2: 普通 | D2: — | E2: 8 | F2: 岩石/矿石统称，无单一矿物
A3: 铜矿石 | B3: 工业矿物 | C3: 普通 | D3: — | E3: 12 | F3: 岩石/矿石统称，无单一矿物
A4: 铝土矿 | B4: 工业矿物 | C4: 普通 | D4: — | E4: 10 | F4: 多种氢氧化铝矿物混合岩石
A5: 锡石 | B5: 工业矿物 | C5: 少见 | D5: SnO₂ | E5: 20
A6: 方铅矿 | B6: 工业矿物 | C6: 普通 | D6: PbS | E6: 10
A7: 闪锌矿 | B7: 工业矿物 | C7: 普通 | D7: ZnS | E7: 10
A8: 辉钼矿 | B8: 工业矿物 | C8: 少见 | D8: MoS₂ | E8: 25
A9: 镍矿 | B9: 工业矿物 | C9: 少见 | D9: — | E9: 22 | F9: 岩石/矿石统称，无单一矿物
A10: 钨矿 | B10: 工业矿物 | C10: 稀有 | D10: — | E10: 45 | F10: 黑钨矿/白钨矿等统称，无单一矿物
A11: 金矿脉 | B11: 工业矿物 | C11: 稀有 | D11: — | E11: 80 | F11: 自然金与围岩混合，无单一化学式
A12: 银矿脉 | B12: 工业矿物 | C12: 少见 | D12: — | E12: 40 | F12: 自然银与围岩混合，无单一化学式
A13: 铬铁矿 | B13: 工业矿物 | C13: 少见 | D13: FeCr₂O₄ | E13: 28
A14: 锰矿 | B14: 工业矿物 | C14: 普通 | D14: — | E14: 15 | F14: 多种锰氧化物矿石统称，无单一矿物
A15: 煤 | B15: 工业矿物 | C15: 普通 | D15: — | E15: 5 | F15: 有机质（植物遗骸炭化），无固定化学式
A16: 褐煤 | B16: 工业矿物 | C16: 普通 | D16: — | E16: 4 | F16: 有机质，无固定化学式
A17: 石油沥青 | B17: 工业矿物 | C17: 少见 | D17: — | E17: 18 | F17: 有机质混合物，无固定化学式
A18: 油页岩 | B18: 工业矿物 | C18: 少见 | D18: — | E18: 16 | F18: 有机质与岩石混合物，无固定化学式
A19: 铀矿 | B19: 工业矿物 | C19: 稀有 | D19: — | E19: 90 | F19: 采集需特殊防护装备；沥青铀矿等统称，主要成分UO₂
A20: 石灰石 | B20: 工业矿物 | C20: 普通 | D20: — | E20: 3 | F20: 地形基底矿：平原（第1档，最低价）；岩石，主要成分CaCO₃
A21: 石膏 | B21: 工业矿物 | C21: 普通 | D21: CaSO₄·2H₂O | E21: 4
A22: 花岗岩 | B22: 工业矿物 | C22: 普通 | D22: — | E22: 8 | F22: 地形基底矿：山地（第3档）；石英+长石+云母等矿物混合岩石
A23: 大理岩 | B23: 工业矿物 | C23: 普通 | D23: — | E23: 18 | F23: 地形基底矿：海底（第5档）；变质石灰岩，主要成分CaCO₃
A24: 石英砂 | B24: 工业矿物 | C24: 普通 | D24: SiO₂ | E24: 12 | F24: 地形基底矿：沙漠（第4档），同时也是山地的常见矿，两边统一定价
A25: 高岭土 | B25: 工业矿物 | C25: 普通 | D25: Al₂Si₂O₅(OH)₄ | E25: 5
A26: 萤石 | B26: 工业矿物 | C26: 少见 | D26: CaF₂ | E26: 18
A27: 重晶石 | B27: 工业矿物 | C27: 普通 | D27: BaSO₄ | E27: 10
A28: 磷灰石 | B28: 工业矿物 | C28: 普通 | D28: Ca₅(PO₄)₃(F,Cl,OH) | E28: 8
A29: 硫磺 | B29: 工业矿物 | C29: 普通 | D29: S | E29: 6
A30: 岩盐 | B30: 工业矿物 | C30: 普通 | D30: NaCl | E30: 4
A31: 石棉 | B31: 工业矿物 | C31: 少见 | D31: — | E31: 15 | F31: 采集需防护装备；矿物族统称（常见为温石棉），无单一化学式
A32: 云母 | B32: 工业矿物 | C32: 普通 | D32: — | E32: 7 | F32: 矿物族统称（白云母/黑云母等），无单一化学式
A33: 滑石 | B33: 工业矿物 | C33: 普通 | D33: Mg₃Si₄O₁₀(OH)₂ | E33: 5
A34: 硼砂 | B34: 工业矿物 | C34: 少见 | D34: Na₂B₄O₇·10H₂O | E34: 14
A35: 黑曜岩 | B35: 工业矿物 | C35: 少见 | D35: — | E35: 25 | F35: 火山玻璃，非结晶矿物，无固定化学式
A36: 泥煤 | B36: 工业矿物 | C36: 普通 | D36: — | E36: 6 | F36: 地形基底矿：沼泽（第2档）；有机质，无固定化学式
A37: 褐铁矿 | B37: 工业矿物 | C37: 普通 | D37: FeO(OH)·nH₂O | E37: 12
A38: 冰 | B38: 工业矿物 | C38: 普通 | D38: H₂O | E38: 25 | F38: 地形基底矿：极地（第6档）；天然、无机、结晶、成分固定，是矿物学承认的正式矿物
A39: 火山岩渣 | B39: 工业矿物 | C39: 普通 | D39: — | E39: 35 | F39: 地形基底矿：火山（第7档）；多孔玄武质火山岩，无固定化学式
A40: 脉石 | B40: 工业矿物 | C40: 普通 | D40: — | E40: 50 | F40: 地形基底矿：深层洞穴（第8档，终局地形，连基底都值钱）；矿脉里包裹矿石的无价值围岩，真实矿业术语，成分常为脉石英或方解石，无单一化学式
...

Sheet 稀有度固定概率设置
A1: 档位 | B1: 数值（可调） | C1: 说明
A2: 传说 | B2: 0.001 | C2: 单个传说级矿物的固定出现概率
A3: 史诗 | B3: 0.005 | C3: 单个史诗级矿物的固定出现概率
A4: 稀有 | B4: 0.02 | C4: 单个稀有级矿物的固定出现概率
A5: 少见 | B5: 0.06 | C5: 单个少见级矿物的固定出现概率
A6: 基底矿 | B6: 0.5 | C6: 每个地形固定一种基底矿，占该地形全部产出概率的一半
A8: 每次入场挖掘次数 | B8: 12 | C8: 一次入场／一局游戏里生成的矿物总数，默认按 10~15 个区间取中间值
A9: 目标利润系数 | B9: 0.85 | C9: 建议门票＝期望总产出×该系数；系数越小，门票越便宜，玩家净赚越多

Sheet 地形刷新表
A1: 地形 | B1: 矿物名称 | C1: 分类 | D1: 稀有度 | E1: 基础售价（金币） | F1: 是否地形基底 | G1: 档位固定概率 | H1: 出现概率（%） | I1: 期望产出贡献（金币）
A2: 平原/浅层土壤 | B2: 石灰石 | C2: =INDEX(矿物图鉴!$B$2:$B$104,MATCH($B2,矿物图鉴!$A$2:$A$104,0)) -> 工业矿物 | D2: =INDEX(矿物图鉴!$C$2:$C$104,MATCH($B2,矿物图鉴!$A$2:$A$104,0)) -> 普通 | E2: =INDEX(矿物图鉴!$E$2:$E$104,MATCH($B2,矿物图鉴!$A$2:$A$104,0)) -> 3 | F2: 是 | G2: =IF($F2="是",稀有度固定概率设置!$B$6,IFERROR(INDEX(稀有度固定概率设置!$B$2:$B$5,MATCH($D2,稀有度固定概率设置!$A$2:$A$5,0)),"")) -> 0.5 | H2: =IF($G2<>"",$G2,(1-SUMIF($A$2:$A$111,$A2,$G$2:$G$111))/COUNTIFS($A$2:$A$111,$A2,$D$2:$D$111,"普通",$F$2:$F$111,"否")) -> 0.5 | I2: =H2*E2 -> 1.5
A3: 平原/浅层土壤 | B3: 煤 | C3: =INDEX(矿物图鉴!$B$2:$B$104,MATCH($B3,矿物图鉴!$A$2:$A$104,0)) -> 工业矿物 | D3: =INDEX(矿物图鉴!$C$2:$C$104,MATCH($B3,矿物图鉴!$A$2:$A$104,0)) -> 普通 | E3: =INDEX(矿物图鉴!$E$2:$E$104,MATCH($B3,矿物图鉴!$A$2:$A$104,0)) -> 5 | F3: 否 | G3: =IF($F3="是",稀有度固定概率设置!$B$6,IFERROR(INDEX(稀有度固定概率设置!$B$2:$B$5,MATCH($D3,稀有度固定概率设置!$A$2:$A$5,0)),"")) | H3: =IF($G3<>"",$G3,(1-SUMIF($A$2:$A$111,$A3,$G$2:$G$111))/COUNTIFS($A$2:$A$111,$A3,$D$2:$D$111,"普通",$F$2:$F$111,"否")) -> 0.044 | I3: =H3*E3 -> 0.22
A4: 平原/浅层土壤 | B4: 铁矿石 | C4: =INDEX(矿物图鉴!$B$2:$B$104,MATCH($B4,矿物图鉴!$A$2:$A$104,0)) -> 工业矿物 | D4: =INDEX(矿物图鉴!$C$2:$C$104,MATCH($B4,矿物图鉴!$A$2:$A$104,0)) -> 普通 | E4: =INDEX(矿物图鉴!$E$2:$E$104,MATCH($B4,矿物图鉴!$A$2:$A$104,0)) -> 8 | F4: 否 | G4: =IF($F4="是",稀有度固定概率设置!$B$6,IFERROR(INDEX(稀有度固定概率设置!$B$2:$B$5,MATCH($D4,稀有度固定概率设置!$A$2:$A$5,0)),"")) | H4: =IF($G4<>"",$G4,(1-SUMIF($A$2:$A$111,$A4,$G$2:$G$111))/COUNTIFS($A$2:$A$111,$A4,$D$2:$D$111,"普通",$F$2:$F$111,"否")) -> 0.044 | I4: =H4*E4 -> 0.352
A5: 平原/浅层土壤 | B5: 岩盐 | C5: =INDEX(矿物图鉴!$B$2:$B$104,MATCH($B5,矿物图鉴!$A$2:$A$104,0)) -> 工业矿物 | D5: =INDEX(矿物图鉴!$C$2:$C$104,MATCH($B5,矿物图鉴!$A$2:$A$104,0)) -> 普通 | E5: =INDEX(矿物图鉴!$E$2:$E$104,MATCH($B5,矿物图鉴!$A$2:$A$104,0)) -> 4 | F5: 否 | G5: =IF($F5="是",稀有度固定概率设置!$B$6,IFERROR(INDEX(稀有度固定概率设置!$B$2:$B$5,MATCH($D5,稀有度固定概率设置!$A$2:$A$5,0)),"")) | H5: =IF($G5<>"",$G5,(1-SUMIF($A$2:$A$111,$A5,$G$2:$G$111))/COUNTIFS($A$2:$A$111,$A5,$D$2:$D$111,"普通",$F$2:$F$111,"否")) -> 0.044 | I5: =H5*E5 -> 0.176
A6: 平原/浅层土壤 | B6: 石膏 | C6: =INDEX(矿物图鉴!$B$2:$B$104,MATCH($B6,矿物图鉴!$A$2:$A$104,0)) -> 工业矿物 | D6: =INDEX(矿物图鉴!$C$2:$C$104,MATCH($B6,矿物图鉴!$A$2:$A$104,0)) -> 普通 | E6: =INDEX(矿物图鉴!$E$2:$E$104,MATCH($B6,矿物图鉴!$A$2:$A$104,0)) -> 4 | F6: 否 | G6: =IF($F6="是",稀有度固定概率设置!$B$6,IFERROR(INDEX(稀有度固定概率设置!$B$2:$B$5,MATCH($D6,稀有度固定概率设置!$A$2:$A$5,0)),"")) | H6: =IF($G6<>"",$G6,(1-SUMIF($A$2:$A$111,$A6,$G$2:$G$111))/COUNTIFS($A$2:$A$111,$A6,$D$2:$D$111,"普通",$F$2:$F$111,"否")) -> 0.044 | I6: =H6*E6 -> 0.176
A7: 平原/浅层土壤 | B7: 云母 | C7: =INDEX(矿物图鉴!$B$2:$B$104,MATCH($B7,矿物图鉴!$A$2:$A$104,0)) -> 工业矿物 | D7: =INDEX(矿物图鉴!$C$2:$C$104,MATCH($B7,矿物图鉴!$A$2:$A$104,0)) -> 普通 | E7: =INDEX(矿物图鉴!$E$2:$E$104,MATCH($B7,矿物图鉴!$A$2:$A$104,0)) -> 7 | F7: 否 | G7: =IF($F7="是",稀有度固定概率设置!$B$6,IFERROR(INDEX(稀有度固定概率设置!$B$2:$B$5,MATCH($D7,稀有度固定概率设置!$A$2:$A$5,0)),"")) | H7: =IF($G7<>"",$G7,(1-SUMIF($A$2:$A$111,$A7,$G$2:$G$111))/COUNTIFS($A$2:$A$111,$A7,$D$2:$D$111,"普通",$F$2:$F$111,"否")) -> 0.044 | I7: =H7*E7 -> 0.308
A8: 平原/浅层土壤 | B8: 玛瑙 | C8: =INDEX(矿物图鉴!$B$2:$B$104,MATCH($B8,矿物图鉴!$A$2:$A$104,0)) -> 常见宝石矿物 | D8: =INDEX(矿物图鉴!$C$2:$C$104,MATCH($B8,矿物图鉴!$A$2:$A$104,0)) -> 普通 | E8: =INDEX(矿物图鉴!$E$2:$E$104,MATCH($B8,矿物图鉴!$A$2:$A$104,0)) -> 40 | F8: 否 | G8: =IF($F8="是",稀有度固定概率设置!$B$6,IFERROR(INDEX(稀有度固定概率设置!$B$2:$B$5,MATCH($D8,稀有度固定概率设置!$A$2:$A$5,0)),"")) | H8: =IF($G8<>"",$G8,(1-SUMIF($A$2:$A$111,$A8,$G$2:$G$111))/COUNTIFS($A$2:$A$111,$A8,$D$2:$D$111,"普通",$F$2:$F$111,"否")) -> 0.044 | I8: =H8*E8 -> 1.76
A9: 平原/浅层土壤 | B9: 方解石晶体 | C9: =INDEX(矿物图鉴!$B$2:$B$104,MATCH($B9,矿物图鉴!$A$2:$A$104,0)) -> 常见宝石矿物 | D9: =INDEX(矿物图鉴!$C$2:$C$104,MATCH($B9,矿物图鉴!$A$2:$A$104,0)) -> 普通 | E9: =INDEX(矿物图鉴!$E$2:$E$104,MATCH($B9,矿物图鉴!$A$2:$A$104,0)) -> 25 | F9: 否 | G9: =IF($F9="是",稀有度固定概率设置!$B$6,IFERROR(INDEX(稀有度固定概率设置!$B$2:$B$5,MATCH($D9,稀有度固定概率设置!$A$2:$A$5,0)),"")) | H9: =IF($G9<>"",$G9,(1-SUMIF($A$2:$A$111,$A9,$G$2:$G$111))/COUNTIFS($A$2:$A$111,$A9,$D$2:$D$111,"普通",$F$2:$F$111,"否")) -> 0.044 | I9: =H9*E9 -> 1.1
A10: 平原/浅层土壤 | B10: 贝壳化石 | C10: =INDEX(矿物图鉴!$B$2:$B$104,MATCH($B10,矿物图鉴!$A$2:$A$104,0)) -> 化石 | D10: =INDEX(矿物图鉴!$C$2:$C$104,MATCH($B10,矿物图鉴!$A$2:$A$104,0)) -> 普通 | E10: =INDEX(矿物图鉴!$E$2:$E$104,MATCH($B10,矿物图鉴!$A$2:$A$104,0)) -> 40 | F10: 否 | G10: =IF($F10="是",稀有度固定概率设置!$B$6,IFERROR(INDEX(稀有度固定概率设置!$B$2:$B$5,MATCH($D10,稀有度固定概率设置!$A$2:$A$5,0)),"")) | H10: =IF($G10<>"",$G10,(1-SUMIF($A$2:$A$111,$A10,$G$2:$G$111))/COUNTIFS($A$2:$A$111,$A10,$D$2:$D$111,"普通",$F$2:$F$111,"否")) -> 0.044 | I10: =H10*E10 -> 1.76
A11: 平原/浅层土壤 | B11: 蕨类植物化石 | C11: =INDEX(矿物图鉴!$B$2:$B$104,MATCH($B11,矿物图鉴!$A$2:$A$104,0)) -> 化石 | D11: =INDEX(矿物图鉴!$C$2:$C$104,MATCH($B11,矿物图鉴!$A$2:$A$104,0)) -> 普通 | E11: =INDEX(矿物图鉴!$E$2:$E$104,MATCH($B11,矿物图鉴!$A$2:$A$104,0)) -> 60 | F11: 否 | G11: =IF($F11="是",稀有度固定概率设置!$B$6,IFERROR(INDEX(稀有度固定概率设置!$B$2:$B$5,MATCH($D11,稀有度固定概率设置!$A$2:$A$5,0)),"")) | H11: =IF($G11<>"",$G11,(1-SUMIF($A$2:$A$111,$A11,$G$2:$G$111))/COUNTIFS($A$2:$A$111,$A11,$D$2:$D$111,"普通",$F$2:$F$111,"否")) -> 0.044 | I11: =H11*E11 -> 2.64
A12: 平原/浅层土壤 | B12: 珊瑚化石 | C12: =INDEX(矿物图鉴!$B$2:$B$104,MATCH($B12,矿物图鉴!$A$2:$A$104,0)) -> 化石 | D12: =INDEX(矿物图鉴!$C$2:$C$104,MATCH($B12,矿物图鉴!$A$2:$A$104,0)) -> 普通 | E12: =INDEX(矿物图鉴!$E$2:$E$104,MATCH($B12,矿物图鉴!$A$2:$A$104,0)) -> 55 | F12: 否 | G12: =IF($F12="是",稀有度固定概率设置!$B$6,IFERROR(INDEX(稀有度固定概率设置!$B$2:$B$5,MATCH($D12,稀有度固定概率设置!$A$2:$A$5,0)),"")) | H12: =IF($G12<>"",$G12,(1-SUMIF($A$2:$A$111,$A12,$G$2:$G$111))/COUNTIFS($A$2:$A$111,$A12,$D$2:$D$111,"普通",$F$2:$F$111,"否")) -> 0.044 | I12: =H12*E12 -> 2.42
A13: 平原/浅层土壤 | B13: 异极矿 | C13: =INDEX(矿物图鉴!$B$2:$B$104,MATCH($B13,矿物图鉴!$A$2:$A$104,0)) -> 珍稀晶体矿物 | D13: =INDEX(矿物图鉴!$C$2:$C$104,MATCH($B13,矿物图鉴!$A$2:$A$104,0)) -> 少见 | E13: =INDEX(矿物图鉴!$E$2:$E$104,MATCH($B13,矿物图鉴!$A$2:$A$104,0)) -> 280 | F13: 否 | G13: =IF($F13="是",稀有度固定概率设置!$B$6,IFERROR(INDEX(稀有度固定概率设置!$B$2:$B$5,MATCH($D13,稀有度固定概率设置!$A$2:$A$5,0)),"")) -> 0.06 | H13: =IF($G13<>"",$G13,(1-SUMIF($A$2:$A$111,$A13,$G$2:$G$111))/COUNTIFS($A$2:$A$111,$A13,$D$2:$D$111,"普通",$F$2:$F$111,"否")) -> 0.06 | I13: =H13*E13 -> 16.8
A14: 平原/浅层土壤 · 合计 | H14: =SUM(H2:H13) -> 1 | I14: =SUM(I2:I13) -> 29.212
A15: 山地/岩层 | B15: 花岗岩 | C15: =INDEX(矿物图鉴!$B$2:$B$104,MATCH($B15,矿物图鉴!$A$2:$A$104,0)) -> 工业矿物 | D15: =INDEX(矿物图鉴!$C$2:$C$104,MATCH($B15,矿物图鉴!$A$2:$A$104,0)) -> 普通 | E15: =INDEX(矿物图鉴!$E$2:$E$104,MATCH($B15,矿物图鉴!$A$2:$A$104,0)) -> 8 | F15: 是 | G15: =IF($F15="是",稀有度固定概率设置!$B$6,IFERROR(INDEX(稀有度固定概率设置!$B$2:$B$5,MATCH($D15,稀有度固定概率设置!$A$2:$A$5,0)),"")) -> 0.5 | H15: =IF($G15<>"",$G15,(1-SUMIF($A$2:$A$111,$A15,$G$2:$G$111))/COUNTIFS($A$2:$A$111,$A15,$D$2:$D$111,"普通",$F$2:$F$111,"否")) -> 0.5 | I15: =H15*E15 -> 4
A16: 山地/岩层 | B16: 铜矿石 | C16: =INDEX(矿物图鉴!$B$2:$B$104,MATCH($B16,矿物图鉴!$A$2:$A$104,0)) -> 工业矿物 | D16: =INDEX(矿物图鉴!$C$2:$C$104,MATCH($B16,矿物图鉴!$A$2:$A$104,0)) -> 普通 | E16: =INDEX(矿物图鉴!$E$2:$E$104,MATCH($B16,矿物图鉴!$A$2:$A$104,0)) -> 12 | F16: 否 | G16: =IF($F16="是",稀有度固定概率设置!$B$6,IFERROR(INDEX(稀有度固定概率设置!$B$2:$B$5,MATCH($D16,稀有度固定概率设置!$A$2:$A$5,0)),"")) | H16: =IF($G16<>"",$G16,(1-SUMIF($A$2:$A$111,$A16,$G$2:$G$111))/COUNTIFS($A$2:$A$111,$A16,$D$2:$D$111,"普通",$F$2:$F$111,"否")) -> 0.043 | I16: =H16*E16 -> 0.516
A17: 山地/岩层 | B17: 锡石 | C17: =INDEX(矿物图鉴!$B$2:$B$104,MATCH($B17,矿物图鉴!$A$2:$A$104,0)) -> 工业矿物 | D17: =INDEX(矿物图鉴!$C$2:$C$104,MATCH($B17,矿物图鉴!$A$2:$A$104,0)) -> 少见 | E17: =INDEX(矿物图鉴!$E$2:$E$104,MATCH($B17,矿物图鉴!$A$2:$A$104,0)) -> 20 | F17: 否 | G17: =IF($F17="是",稀有度固定概率设置!$B$6,IFERROR(INDEX(稀有度固定概率设置!$B$2:$B$5,MATCH($D17,稀有度固定概率设置!$A$2:$A$5,0)),"")) -> 0.06 | H17: =IF($G17<>"",$G17,(1-SUMIF($A$2:$A$111,$A17,$G$2:$G$111))/COUNTIFS($A$2:$A$111,$A17,$D$2:$D$111,"普通",$F$2:$F$111,"否")) -> 0.06 | I17: =H17*E17 -> 1.2
A18: 山地/岩层 | B18: 云母 | C18: =INDEX(矿物图鉴!$B$2:$B$104,MATCH($B18,矿物图鉴!$A$2:$A$104,0)) -> 工业矿物 | D18: =INDEX(矿物图鉴!$C$2:$C$104,MATCH($B18,矿物图鉴!$A$2:$A$104,0)) -> 普通 | E18: =INDEX(矿物图鉴!$E$2:$E$104,MATCH($B18,矿物图鉴!$A$2:$A$104,0)) -> 7 | F18: 否 | G18: =IF($F18="是",稀有度固定概率设置!$B$6,IFERROR(INDEX(稀有度固定概率设置!$B$2:$B$5,MATCH($D18,稀有度固定概率设置!$A$2:$A$5,0)),"")) | H18: =IF($G18<>"",$G18,(1-SUMIF($A$2:$A$111,$A18,$G$2:$G$111))/COUNTIFS($A$2:$A$111,$A18,$D$2:$D$111,"普通",$F$2:$F$111,"否")) -> 0.043 | I18: =H18*E18 -> 0.301
A19: 山地/岩层 | B19: 石英砂 | C19: =INDEX(矿物图鉴!$B$2:$B$104,MATCH($B19,矿物图鉴!$A$2:$A$104,0)) -> 工业矿物 | D19: =INDEX(矿物图鉴!$C$2:$C$104,MATCH($B19,矿物图鉴!$A$2:$A$104,0)) -> 普通 | E19: =INDEX(矿物图鉴!$E$2:$E$104,MATCH($B19,矿物图鉴!$A$2:$A$104,0)) -> 12 | F19: 否 | G19: =IF($F19="是",稀有度固定概率设置!$B$6,IFERROR(INDEX(稀有度固定概率设置!$B$2:$B$5,MATCH($D19,稀有度固定概率设置!$A$2:$A$5,0)),"")) | H19: =IF($G19<>"",$G19,(1-SUMIF($A$2:$A$111,$A19,$G$2:$G$111))/COUNTIFS($A$2:$A$111,$A19,$D$2:$D$111,"普通",$F$2:$F$111,"否")) -> 0.043 | I19: =H19*E19 -> 0.516
A20: 山地/岩层 | B20: 石榴石 | C20: =INDEX(矿物图鉴!$B$2:$B$104,MATCH($B20,矿物图鉴!$A$2:$A$104,0)) -> 常见宝石矿物 | D20: =INDEX(矿物图鉴!$C$2:$C$104,MATCH($B20,矿物图鉴!$A$2:$A$104,0)) -> 少见 | E20: =INDEX(矿物图鉴!$E$2:$E$104,MATCH($B20,矿物图鉴!$A$2:$A$104,0)) -> 150 | F20: 否 | G20: =IF($F20="是",稀有度固定概率设置!$B$6,IFERROR(INDEX(稀有度固定概率设置!$B$2:$B$5,MATCH($D20,稀有度固定概率设置!$A$2:$A$5,0)),"")) -> 0.06 | H20: =IF($G20<>"",$G20,(1-SUMIF($A$2:$A$111,$A20,$G$2:$G$111))/COUNTIFS($A$2:$A$111,$A20,$D$2:$D$111,"普通",$F$2:$F$111,"否")) -> 0.06 | I20: =H20*E20 -> 9
A21: 山地/岩层 | B21: 白水晶 | C21: =INDEX(矿物图鉴!$B$2:$B$104,MATCH($B21,矿物图鉴!$A$2:$A$104,0)) -> 常见宝石矿物 | D21: =INDEX(矿物图鉴!$C$2:$C$104,MATCH($B21,矿物图鉴!$A$2:$A$104,0)) -> 普通 | E21: =INDEX(矿物图鉴!$E$2:$E$104,MATCH($B21,矿物图鉴!$A$2:$A$104,0)) -> 30 | F21: 否 | G21: =IF($F21="是",稀有度固定概率设置!$B$6,IFERROR(INDEX(稀有度固定概率设置!$B$2:$B$5,MATCH($D21,稀有度固定概率设置!$A$2:$A$5,0)),"")) | H21: =IF($G21<>"",$G21,(1-SUMIF($A$2:$A$111,$A21,$G$2:$G$111))/COUNTIFS($A$2:$A$111,$A21,$D$2:$D$111,"普通",$F$2:$F$111,"否")) -> 0.043 | I21: =H21*E21 -> 1.29
A22: 山地/岩层 | B22: 方解石晶体 | C22: =INDEX(矿物图鉴!$B$2:$B$104,MATCH($B22,矿物图鉴!$A$2:$A$104,0)) -> 常见宝石矿物 | D22: =INDEX(矿物图鉴!$C$2:$C$104,MATCH($B22,矿物图鉴!$A$2:$A$104,0)) -> 普通 | E22: =INDEX(矿物图鉴!$E$2:$E$104,MATCH($B22,矿物图鉴!$A$2:$A$104,0)) -> 25 | F22: 否 | G22: =IF($F22="是",稀有度固定概率设置!$B$6,IFERROR(INDEX(稀有度固定概率设置!$B$2:$B$5,MATCH($D22,稀有度固定概率设置!$A$2:$A$5,0)),"")) | H22: =IF($G22<>"",$G22,(1-SUMIF($A$2:$A$111,$A22,$G$2:$G$111))/COUNTIFS($A$2:$A$111,$A22,$D$2:$D$111,"普通",$F$2:$F$111,"否")) -> 0.043 | I22: =H22*E22 -> 1.075
A23: 山地/岩层 | B23: 金红石 | C23: =INDEX(矿物图鉴!$B$2:$B$104,MATCH($B23,矿物图鉴!$A$2:$A$104,0)) -> 珍稀晶体矿物 | D23: =INDEX(矿物图鉴!$C$2:$C$104,MATCH($B23,矿物图鉴!$A$2:$A$104,0)) -> 稀有 | E23: =INDEX(矿物图鉴!$E$2:$E$104,MATCH($B23,矿物图鉴!$A$2:$A$104,0)) -> 550 | F23: 否 | G23: =IF($F23="是",稀有度固定概率设置!$B$6,IFERROR(INDEX(稀有度固定概率设置!$B$2:$B$5,MATCH($D23,稀有度固定概率设置!$A$2:$A$5,0)),"")) -> 0.02 | H23: =IF($G23<>"",$G23,(1-SUMIF($A$2:$A$111,$A23,$G$2:$G$111))/COUNTIFS($A$2:$A$111,$A23,$D$2:$D$111,"普通",$F$2:$F$111,"否")) -> 0.02 | I23: =H23*E23 -> 11
A24: 山地/岩层 | B24: 蓝柱石 | C24: =INDEX(矿物图鉴!$B$2:$B$104,MATCH($B24,矿物图鉴!$A$2:$A$104,0)) -> 珍稀晶体矿物 | D24: =INDEX(矿物图鉴!$C$2:$C$104,MATCH($B24,矿物图鉴!$A$2:$A$104,0)) -> 稀有 | E24: =INDEX(矿物图鉴!$E$2:$E$104,MATCH($B24,矿物图鉴!$A$2:$A$104,0)) -> 600 | F24: 否 | G24: =IF($F24="是",稀有度固定概率设置!$B$6,IFERROR(INDEX(稀有度固定概率设置!$B$2:$B$5,MATCH($D24,稀有度固定概率设置!$A$2:$A$5,0)),"")) -> 0.02 | H24: =IF($G24<>"",$G24,(1-SUMIF($A$2:$A$111,$A24,$G$2:$G$111))/COUNTIFS($A$2:$A$111,$A24,$D$2:$D$111,"普通",$F$2:$F$111,"否")) -> 0.02 | I24: =H24*E24 -> 12
A25: 山地/岩层 | B25: 三叶虫化石 | C25: =INDEX(矿物图鉴!$B$2:$B$104,MATCH($B25,矿物图鉴!$A$2:$A$104,0)) -> 化石 | D25: =INDEX(矿物图鉴!$C$2:$C$104,MATCH($B25,矿物图鉴!$A$2:$A$104,0)) -> 少见 | E25: =INDEX(矿物图鉴!$E$2:$E$104,MATCH($B25,矿物图鉴!$A$2:$A$104,0)) -> 200 | F25: 否 | G25: =IF($F25="是",稀有度固定概率设置!$B$6,IFERROR(INDEX(稀有度固定概率设置!$B$2:$B$5,MATCH($D25,稀有度固定概率设置!$A$2:$A$5,0)),"")) -> 0.06 | H25: =IF($G25<>"",$G25,(1-SUMIF($A$2:$A$111,$A25,$G$2:$G$111))/COUNTIFS($A$2:$A$111,$A25,$D$2:$D$111,"普通",$F$2:$F$111,"否")) -> 0.06 | I25: =H25*E25 -> 12
A26: 山地/岩层 | B26: 硅化木 | C26: =INDEX(矿物图鉴!$B$2:$B$104,MATCH($B26,矿物图鉴!$A$2:$A$104,0)) -> 化石 | D26: =INDEX(矿物图鉴!$C$2:$C$104,MATCH($B26,矿物图鉴!$A$2:$A$104,0)) -> 少见 | E26: =INDEX(矿物图鉴!$E$2:$E$104,MATCH($B26,矿物图鉴!$A$2:$A$104,0)) -> 220 | F26: 否 | G26: =IF($F26="是",稀有度固定概率设置!$B$6,IFERROR(INDEX(稀有度固定概率设置!$B$2:$B$5,MATCH($D26,稀有度固定概率设置!$A$2:$A$5,0)),"")) -> 0.06 | H26: =IF($G26<>"",$G26,(1-SUMIF($A$2:$A$111,$A26,$G$2:$G$111))/COUNTIFS($A$2:$A$111,$A26,$D$2:$D$111,"普通",$F$2:$F$111,"否")) -> 0.06 | I26: =H26*E26 -> 13.2
A27: 山地/岩层 | B27: 祖母绿 | C27: =INDEX(矿物图鉴!$B$2:$B$104,MATCH($B27,矿物图鉴!$A$2:$A$104,0)) -> 常见宝石矿物 | D27: =INDEX(矿物图鉴!$C$2:$C$104,MATCH($B27,矿物图鉴!$A$2:$A$104,0)) -> 史诗 | E27: =INDEX(矿物图鉴!$E$2:$E$104,MATCH($B27,矿物图鉴!$A$2:$A$104,0)) -> 2000 | F27: 否 | G27: =IF($F27="是",稀有度固定概率设置!$B$6,IFERROR(INDEX(稀有度固定概率设置!$B$2:$B$5,MATCH($D27,稀有度固定概率设置!$A$2:$A$5,0)),"")) -> 0.005 | H27: =IF($G27<>"",$G27,(1-SUMIF($A$2:$A$111,$A27,$G$2:$G$111))/COUNTIFS($A$2:$A$111,$A27,$D$2:$D$111,"普通",$F$2:$F$111,"否")) -> 0.005 | I27: =H27*E27 -> 10
A28: 山地/岩层 · 合计 | H28: =SUM(H15:H27) -> 1 | I28: =SUM(I15:I27) -> 76.098
A29: 深层洞穴/矿脉核心 | B29: 脉石 | C29: =INDEX(矿物图鉴!$B$2:$B$104,MATCH($B29,矿物图鉴!$A$2:$A$104,0)) -> 工业矿物 | D29: =INDEX(矿物图鉴!$C$2:$C$104,MATCH($B29,矿物图鉴!$A$2:$A$104,0)) -> 普通 | E29: =INDEX(矿物图鉴!$E$2:$E$104,MATCH($B29,矿物图鉴!$A$2:$A$104,0)) -> 50 | F29: 是 | G29: =IF($F29="是",稀有度固定概率设置!$B$6,IFERROR(INDEX(稀有度固定概率设置!$B$2:$B$5,MATCH($D29,稀有度固定概率设置!$A$2:$A$5,0)),"")) -> 0.5 | H29: =IF($G29<>"",$G29,(1-SUMIF($A$2:$A$111,$A29,$G$2:$G$111))/COUNTIFS($A$2:$A$111,$A29,$D$2:$D$111,"普通",$F$2:$F$111,"否")) -> 0.5 | I29: =H29*E29 -> 25
A30: 深层洞穴/矿脉核心 | B30: 金矿脉 | C30: =INDEX(矿物图鉴!$B$2:$B$104,MATCH($B30,矿物图鉴!$A$2:$A$104,0)) -> 工业矿物 | D30: =INDEX(矿物图鉴!$C$2:$C$104,MATCH($B30,矿物图鉴!$A$2:$A$104,0)) -> 稀有 | E30: =INDEX(矿物图鉴!$E$2:$E$104,MATCH($B30,矿物图鉴!$A$2:$A$104,0)) -> 80 | F30: 否 | G30: =IF($F30="是",稀有度固定概率设置!$B$6,IFERROR(INDEX(稀有度固定概率设置!$B$2:$B$5,MATCH($D30,稀有度固定概率设置!$A$2:$A$5,0)),"")) -> 0.02 | H30: =IF($G30<>"",$G30,(1-SUMIF($A$2:$A$111,$A30,$G$2:$G$111))/COUNTIFS($A$2:$A$111,$A30,$D$2:$D$111,"普通",$F$2:$F$111,"否")) -> 0.02 | I30: =H30*E30 -> 1.6
A31: 深层洞穴/矿脉核心 | B31: 银矿脉 | C31: =INDEX(矿物图鉴!$B$2:$B$104,MATCH($B31,矿物图鉴!$A$2:$A$104,0)) -> 工业矿物 | D31: =INDEX(矿物图鉴!$C$2:$C$104,MATCH($B31,矿物图鉴!$A$2:$A$104,0)) -> 少见 | E31: =INDEX(矿物图鉴!$E$2:$E$104,MATCH($B31,矿物图鉴!$A$2:$A$104,0)) -> 40 | F31: 否 | G31: =IF($F31="是",稀有度固定概率设置!$B$6,IFERROR(INDEX(稀有度固定概率设置!$B$2:$B$5,MATCH($D31,稀有度固定概率设置!$A$2:$A$5,0)),"")) -> 0.06 | H31: =IF($G31<>"",$G31,(1-SUMIF($A$2:$A$111,$A31,$G$2:$G$111))/COUNTIFS($A$2:$A$111,$A31,$D$2:$D$111,"普通",$F$2:$F$111,"否")) -> 0.06 | I31: =H31*E31 -> 2.4
A32: 深层洞穴/矿脉核心 | B32: 钨矿 | C32: =INDEX(矿物图鉴!$B$2:$B$104,MATCH($B32,矿物图鉴!$A$2:$A$104,0)) -> 工业矿物 | D32: =INDEX(矿物图鉴!$C$2:$C$104,MATCH($B32,矿物图鉴!$A$2:$A$104,0)) -> 稀有 | E32: =INDEX(矿物图鉴!$E$2:$E$104,MATCH($B32,矿物图鉴!$A$2:$A$104,0)) -> 45 | F32: 否 | G32: =IF($F32="是",稀有度固定概率设置!$B$6,IFERROR(INDEX(稀有度固定概率设置!$B$2:$B$5,MATCH($D32,稀有度固定概率设置!$A$2:$A$5,0)),"")) -> 0.02 | H32: =IF($G32<>"",$G32,(1-SUMIF($A$2:$A$111,$A32,$G$2:$G$111))/COUNTIFS($A$2:$A$111,$A32,$D$2:$D$111,"普通",$F$2:$F$111,"否")) -> 0.02 | I32: =H32*E32 -> 0.9
A33: 深层洞穴/矿脉核心 | B33: 萤石 | C33: =INDEX(矿物图鉴!$B$2:$B$104,MATCH($B33,矿物图鉴!$A$2:$A$104,0)) -> 工业矿物 | D33: =INDEX(矿物图鉴!$C$2:$C$104,MATCH($B33,矿物图鉴!$A$2:$A$104,0)) -> 少见 | E33: =INDEX(矿物图鉴!$E$2:$E$104,MATCH($B33,矿物图鉴!$A$2:$A$104,0)) -> 18 | F33: 否 | G33: =IF($F33="是",稀有度固定概率设置!$B$6,IFERROR(INDEX(稀有度固定概率设置!$B$2:$B$5,MATCH($D33,稀有度固定概率设置!$A$2:$A$5,0)),"")) -> 0.06 | H33: =IF($G33<>"",$G33,(1-SUMIF($A$2:$A$111,$A33,$G$2:$G$111))/COUNTIFS($A$2:$A$111,$A33,$D$2:$D$111,"普通",$F$2:$F$111,"否")) -> 0.06 | I33: =H33*E33 -> 1.08
A34: 深层洞穴/矿脉核心 | B34: 紫水晶 | C34: =INDEX(矿物图鉴!$B$2:$B$104,MATCH($B34,矿物图鉴!$A$2:$A$104,0)) -> 常见宝石矿物 | D34: =INDEX(矿物图鉴!$C$2:$C$104,MATCH($B34,矿物图鉴!$A$2:$A$104,0)) -> 普通 | E34: =INDEX(矿物图鉴!$E$2:$E$104,MATCH($B34,矿物图鉴!$A$2:$A$104,0)) -> 60 | F34: 否 | G34: =IF($F34="是",稀有度固定概率设置!$B$6,IFERROR(INDEX(稀有度固定概率设置!$B$2:$B$5,MATCH($D34,稀有度固定概率设置!$A$2:$A$5,0)),"")) | H34: =IF($G34<>"",$G34,(1-SUMIF($A$2:$A$111,$A34,$G$2:$G$111))/COUNTIFS($A$2:$A$111,$A34,$D$2:$D$111,"普通",$F$2:$F$111,"否")) -> 0.045666667 | I34: =H34*E34 -> 2.74
A35: 深层洞穴/矿脉核心 | B35: 黄水晶 | C35: =INDEX(矿物图鉴!$B$2:$B$104,MATCH($B35,矿物图鉴!$A$2:$A$104,0)) -> 常见宝石矿物 | D35: =INDEX(矿物图鉴!$C$2:$C$104,MATCH($B35,矿物图鉴!$A$2:$A$104,0)) -> 普通 | E35: =INDEX(矿物图鉴!$E$2:$E$104,MATCH($B35,矿物图鉴!$A$2:$A$104,0)) -> 55 | F35: 否 | G35: =IF($F35="是",稀有度固定概率设置!$B$6,IFERROR(INDEX(稀有度固定概率设置!$B$2:$B$5,MATCH($D35,稀有度固定概率设置!$A$2:$A$5,0)),"")) | H35: =IF($G35<>"",$G35,(1-SUMIF($A$2:$A$111,$A35,$G$2:$G$111))/COUNTIFS($A$2:$A$111,$A35,$D$2:$D$111,"普通",$F$2:$F$111,"否")) -> 0.045666667 | I35: =H35*E35 -> 2.5116667
A36: 深层洞穴/矿脉核心 | B36: 烟晶 | C36: =INDEX(矿物图鉴!$B$2:$B$104,MATCH($B36,矿物图鉴!$A$2:$A$104,0)) -> 常见宝石矿物 | D36: =INDEX(矿物图鉴!$C$2:$C$104,MATCH($B36,矿物图鉴!$A$2:$A$104,0)) -> 普通 | E36: =INDEX(矿物图鉴!$E$2:$E$104,MATCH($B36,矿物图鉴!$A$2:$A$104,0)) -> 50 | F36: 否 | G36: =IF($F36="是",稀有度固定概率设置!$B$6,IFERROR(INDEX(稀有度固定概率设置!$B$2:$B$5,MATCH($D36,稀有度固定概率设置!$A$2:$A$5,0)),"")) | H36: =IF($G36<>"",$G36,(1-SUMIF($A$2:$A$111,$A36,$G$2:$G$111))/COUNTIFS($A$2:$A$111,$A36,$D$2:$D$111,"普通",$F$2:$F$111,"否")) -> 0.045666667 | I36: =H36*E36 -> 2.2833333
A37: 深层洞穴/矿脉核心 | B37: 磷叶石 | C37: =INDEX(矿物图鉴!$B$2:$B$104,MATCH($B37,矿物图鉴!$A$2:$A$104,0)) -> 珍稀晶体矿物 | D37: =INDEX(矿物图鉴!$C$2:$C$104,MATCH($B37,矿物图鉴!$A$2:$A$104,0)) -> 传说 | E37: =INDEX(矿物图鉴!$E$2:$E$104,MATCH($B37,矿物图鉴!$A$2:$A$104,0)) -> 1500 | F37: 否 | G37: =IF($F37="是",稀有度固定概率设置!$B$6,IFERROR(INDEX(稀有度固定概率设置!$B$2:$B$5,MATCH($D37,稀有度固定概率设置!$A$2:$A$5,0)),"")) -> 0.001 | H37: =IF($G37<>"",$G37,(1-SUMIF($A$2:$A$111,$A37,$G$2:$G$111))/COUNTIFS($A$2:$A$111,$A37,$D$2:$D$111,"普通",$F$2:$F$111,"否")) -> 0.001 | I37: =H37*E37 -> 1.5
A38: 深层洞穴/矿脉核心 | B38: 幽灵水晶 | C38: =INDEX(矿物图鉴!$B$2:$B$104,MATCH($B38,矿物图鉴!$A$2:$A$104,0)) -> 珍稀晶体矿物 | D38: =INDEX(矿物图鉴!$C$2:$C$104,MATCH($B38,矿物图鉴!$A$2:$A$104,0)) -> 史诗 | E38: =INDEX(矿物图鉴!$E$2:$E$104,MATCH($B38,矿物图鉴!$A$2:$A$104,0)) -> 1900 | F38: 否 | G38: =IF($F38="是",稀有度固定概率设置!$B$6,IFERROR(INDEX(稀有度固定概率设置!$B$2:$B$5,MATCH($D38,稀有度固定概率设置!$A$2:$A$5,0)),"")) -> 0.005 | H38: =IF($G38<>"",$G38,(1-SUMIF($A$2:$A$111,$A38,$G$2:$G$111))/COUNTIFS($A$2:$A$111,$A38,$D$2:$D$111,"普通",$F$2:$F$111,"否")) -> 0.005 | I38: =H38*E38 -> 9.5
A39: 深层洞穴/矿脉核心 | B39: 蓝锥矿 | C39: =INDEX(矿物图鉴!$B$2:$B$104,MATCH($B39,矿物图鉴!$A$2:$A$104,0)) -> 珍稀晶体矿物 | D39: =INDEX(矿物图鉴!$C$2:$C$104,MATCH($B39,矿物图鉴!$A$2:$A$104,0)) -> 史诗 | E39: =INDEX(矿物图鉴!$E$2:$E$104,MATCH($B39,矿物图鉴!$A$2:$A$104,0)) -> 1800 | F39: 否 | G39: =IF($F39="是",稀有度固定概率设置!$B$6,IFERROR(INDEX(稀有度固定概率设置!$B$2:$B$5,MATCH($D39,稀有度固定概率设置!$A$2:$A$5,0)),"")) -> 0.005 | H39: =IF($G39<>"",$G39,(1-SUMIF($A$2:$A$111,$A39,$G$2:$G$111))/COUNTIFS($A$2:$A$111,$A39,$D$2:$D$111,"普通",$F$2:$F$111,"否")) -> 0.005 | I39: =H39*E39 -> 9
A40: 深层洞穴/矿脉核心 | B40: 天青石 | C40: =INDEX(矿物图鉴!$B$2:$B$104,MATCH($B40,矿物图鉴!$A$2:$A$104,0)) -> 常见宝石矿物 | D40: =INDEX(矿物图鉴!$C$2:$C$104,MATCH($B40,矿物图鉴!$A$2:$A$104,0)) -> 少见 | E40: =INDEX(矿物图鉴!$E$2:$E$104,MATCH($B40,矿物图鉴!$A$2:$A$104,0)) -> 95 | F40: 否 | G40: =IF($F40="是",稀有度固定概率设置!$B$6,IFERROR(INDEX(稀有度固定概率设置!$B$2:$B$5,MATCH($D40,稀有度固定概率设置!$A$2:$A$5,0)),"")) -> 0.06 | H40: =IF($G40<>"",$G40,(1-SUMIF($A$2:$A$111,$A40,$G$2:$G$111))/COUNTIFS($A$2:$A$111,$A40,$D$2:$D$111,"普通",$F$2:$F$111,"否")) -> 0.06 | I40: =H40*E40 -> 5.7
...

Sheet 地形经济测算
A1: 地形 | B1: 单次挖掘期望产出（金币） | C1: 每次入场挖掘次数 | D1: 期望总产出（金币） | E1: 建议单次入场费（金币） | F1: 预期净利润（金币） | G1: 净利润率 | H1: 是否免费地形
A2: 平原/浅层土壤 | B2: =SUMIF(地形刷新表!$A$2:$A$111,A2,地形刷新表!$I$2:$I$111) -> 29.212 | C2: =稀有度固定概率设置!$B$8 -> 12 | D2: =B2*C2 -> 350.544 | E2: =IF($H2="是",0,ROUND(D2*稀有度固定概率设置!$B$9,-1)) -> 0 | F2: =D2-E2 -> 350.544 | G2: =IF(E2=0,"—",F2/E2) -> — | H2: 是
A3: 山地/岩层 | B3: =SUMIF(地形刷新表!$A$2:$A$111,A3,地形刷新表!$I$2:$I$111) -> 76.098 | C3: =稀有度固定概率设置!$B$8 -> 12 | D3: =B3*C3 -> 913.176 | E3: =IF($H3="是",0,ROUND(D3*稀有度固定概率设置!$B$9,-1)) -> 780 | F3: =D3-E3 -> 133.176 | G3: =IF(E3=0,"—",F3/E3) -> 0.17073846 | H3: 否
A4: 深层洞穴/矿脉核心 | B4: =SUMIF(地形刷新表!$A$2:$A$111,A4,地形刷新表!$I$2:$I$111) -> 119.215 | C4: =稀有度固定概率设置!$B$8 -> 12 | D4: =B4*C4 -> 1430.58 | E4: =IF($H4="是",0,ROUND(D4*稀有度固定概率设置!$B$9,-1)) -> 1220 | F4: =D4-E4 -> 210.58 | G4: =IF(E4=0,"—",F4/E4) -> 0.17260656 | H4: 否
A5: 火山/熔岩区 | B5: =SUMIF(地形刷新表!$A$2:$A$111,A5,地形刷新表!$I$2:$I$111) -> 71.548 | C5: =稀有度固定概率设置!$B$8 -> 12 | D5: =B5*C5 -> 858.576 | E5: =IF($H5="是",0,ROUND(D5*稀有度固定概率设置!$B$9,-1)) -> 730 | F5: =D5-E5 -> 128.576 | G5: =IF(E5=0,"—",F5/E5) -> 0.17613151 | H5: 否
A6: 沙漠 | B6: =SUMIF(地形刷新表!$A$2:$A$111,A6,地形刷新表!$I$2:$I$111) -> 80.686 | C6: =稀有度固定概率设置!$B$8 -> 12 | D6: =B6*C6 -> 968.232 | E6: =IF($H6="是",0,ROUND(D6*稀有度固定概率设置!$B$9,-1)) -> 820 | F6: =D6-E6 -> 148.232 | G6: =IF(E6=0,"—",F6/E6) -> 0.18077073 | H6: 否
A7: 极地/雪原冰川 | B7: =SUMIF(地形刷新表!$A$2:$A$111,A7,地形刷新表!$I$2:$I$111) -> 76.584 | C7: =稀有度固定概率设置!$B$8 -> 12 | D7: =B7*C7 -> 919.008 | E7: =IF($H7="是",0,ROUND(D7*稀有度固定概率设置!$B$9,-1)) -> 780 | F7: =D7-E7 -> 139.008 | G7: =IF(E7=0,"—",F7/E7) -> 0.17821538 | H7: 否
A8: 沼泽/湿地 | B8: =SUMIF(地形刷新表!$A$2:$A$111,A8,地形刷新表!$I$2:$I$111) -> 79.60625 | C8: =稀有度固定概率设置!$B$8 -> 12 | D8: =B8*C8 -> 955.275 | E8: =IF($H8="是",0,ROUND(D8*稀有度固定概率设置!$B$9,-1)) -> 810 | F8: =D8-E8 -> 145.275 | G8: =IF(E8=0,"—",F8/E8) -> 0.17935185 | H8: 否
A9: 海底/海岸礁石 | B9: =SUMIF(地形刷新表!$A$2:$A$111,A9,地形刷新表!$I$2:$I$111) -> 87.858333 | C9: =稀有度固定概率设置!$B$8 -> 12 | D9: =B9*C9 -> 1054.3 | E9: =IF($H9="是",0,ROUND(D9*稀有度固定概率设置!$B$9,-1)) -> 900 | F9: =D9-E9 -> 154.3 | G9: =IF(E9=0,"—",F9/E9) -> 0.17144444 | H9: 否
A11: 建议单次入场费 = 期望总产出 × 目标利润系数（在「稀有度固定概率设置」表里可调），四舍五入到十位；「是否免费地形」标为「是」的地形（默认平原）直接入场费归零，忽略公式结果。
A12: 平原作为新手起始地形免费开放，方便玩家零门槛上手、攒第一桶金去解锁后面的地形；想让别的地形也免费，把对应行「是否免费地形」改成「是」即可。
A13: 也就是说，只要玩家把入场后的挖掘次数都用满、且卖掉所有挖到的矿物，长期期望是净赚的；单次运气不好（净利润率为负）也正常，这是「概率游戏」而不是「保底游戏」。

Sheet 地形解锁顺序
A1: 解锁顺序 | B1: 地形 | C1: 解锁前置 （累计已发现矿物种类数） | D1: 该地形矿物种类数 | E1: 备注
A2: 1 | B2: 平原/浅层土壤 | C2: 0 | D2: =COUNTIF(地形刷新表!$A$2:$A$111,B2) -> 12 | E2: 新手起始地形，免费开放
A3: 2 | B3: 沼泽/湿地 | C3: 8 | D3: =COUNTIF(地形刷新表!$A$2:$A$111,B3) -> 11
A4: 3 | B4: 山地/岩层 | C4: 16 | D4: =COUNTIF(地形刷新表!$A$2:$A$111,B4) -> 13
A5: 4 | B5: 沙漠 | C5: 24 | D5: =COUNTIF(地形刷新表!$A$2:$A$111,B5) -> 13
A6: 5 | B6: 海底/海岸礁石 | C6: 32 | D6: =COUNTIF(地形刷新表!$A$2:$A$111,B6) -> 11 | E6: 可结合“渔具/潜水装备”等前置道具一起设计
A7: 6 | B7: 极地/雪原冰川 | C7: 42 | D7: =COUNTIF(地形刷新表!$A$2:$A$111,B7) -> 11 | E7: 可结合“防寒装备”前置道具
A8: 7 | B8: 火山/熔岩区 | C8: 52 | D8: =COUNTIF(地形刷新表!$A$2:$A$111,B8) -> 13 | E8: 含钻石顶级稀有产出，可结合“耐热装备”前置道具
A9: 8 | B9: 深层洞穴/矿脉核心 | C9: 64 | D9: =COUNTIF(地形刷新表!$A$2:$A$111,B9) -> 18 | E9: 含红宝石、翡翠顶级稀有产出，建议作为终局地形
B11: 黄色底色列为建议调整数值：解锁前置数量可自由改动。解锁只看「累计已发现矿物种类数」，不收一次性解锁费——门槛纯粹是探索进度，不是付费墙。
B12: 单次入场费只在「地形经济测算」表里维护一份（建议单次入场费列），这里不重复列出，避免两处数字不同步。
